Workbook

Sheet Estimativa
C1: Métrica Função de Implementação - Estimativa
A6: Cliente: | C6: HOSPITAL UNIVERSITÁRIO VITALIS / UCSAL
A7: Projeto: | C7: SISTEMA DE GESTÃO HOSPITALAR INTELIGENTE VITALIS (VERSÃO 2.0)
A8: Estimado por: | C8: DAVI DOS SANTOS RIBEIRO
A9: Data Estimativa: | C9: 46316
B12: Função de Implementação | D12: Qtde de programas | E12: Caracteristicas Internas de Programa | I12: Tipo de Serviço | L12: Ambiente de Desenvolvimento | M12: Tamanho | N12: Fatores de Esforço | Q12: Esforço de Construção (Horas) | R12: Esforço Especificação Lógica/Física (Horas) | S12: Esforço Testes (Horas) | T12: Total de Esforço Bruto (Horas)
B13: Identificação | C13: Descrição | E13: Programa com Tela | F13: Programa sem Tela | G13: Programa com Relatório | H13: Qtde Tabelas | I13: Plataforma | J13: Linguagem | K13: Interfaces Externas | L13: Tipo de Serviço | M13: Qtde Pontos de Implementação | N13: Esforço p/ Execução do Serviço | O13: Reutilização de Objetos | P13: Complexidade de Manutenção
B14: 1 | C14: MFI-01: Cadastro de Pacientes, Validação CNS/CPF e Recepção | D14: 2 | E14: 4 | F14: 2 | G14: 1 | H14: 2 | I14: 1 | J14: 3 | K14: 3 | L14: 2 | M14: =SUM(E14:L14)*D14 -> 36 | N14: 1.2 | O14: 0.75 | P14: 1.2 | Q14: =M14*N14*O14*P14 -> 38.88 | R14: =(Q14*25)/55 -> 17.67 | S14: =(Q14*20)/55 -> 14.14 | T14: =SUM(Q14:S14) -> 70.69
B15: 2 | C15: MFI-02: Acolhimento e Triagem de Manchester com Voz | D15: 2 | E15: 4 | F15: 3 | G15: 1 | H15: 2 | I15: 1 | J15: 3 | K15: 3 | L15: 2 | M15: =SUM(E15:L15)*D15 -> 38 | N15: 1.2 | O15: 0.75 | P15: 1.8 | Q15: =M15*N15*O15*P15 -> 61.56 | R15: =(Q15*25)/55 -> 27.98 | S15: =(Q15*20)/55 -> 22.39 | T15: =SUM(Q15:S15) -> 111.93
B16: 3 | C16: MFI-03: Motor Preditivo de Sepse e Deterioração (qSOFA/NEWS2) | D16: 2 | E16: 2 | F16: 3 | G16: 2 | H16: 2 | I16: 2 | J16: 3 | K16: 3 | L16: 2 | M16: =SUM(E16:L16)*D16 -> 38 | N16: 1.2 | O16: 1 | P16: 2.4 | Q16: =M16*N16*O16*P16 -> 109.44 | R16: =(Q16*25)/55 -> 49.75 | S16: =(Q16*20)/55 -> 39.8 | T16: =SUM(Q16:S16) -> 198.98
B17: 4 | C17: MFI-04: Gestão Dinâmica e Alocação Preditiva de Leitos (LOS) | D17: 2 | E17: 4 | F17: 2 | G17: 2 | H17: 2 | I17: 1 | J17: 3 | K17: 2 | L17: 2 | M17: =SUM(E17:L17)*D17 -> 36 | N17: 1.2 | O17: 0.75 | P17: 1.8 | Q17: =M17*N17*O17*P17 -> 58.32 | R17: =(Q17*25)/55 -> 26.51 | S17: =(Q17*20)/55 -> 21.21 | T17: =SUM(Q17:S17) -> 106.04
B18: 5 | C18: MFI-05: Prontuário Eletrônico (PEP) e Evolução Estruturada | D18: 3 | E18: 4 | F18: 3 | G18: 3 | H18: 3 | I18: 1 | J18: 3 | K18: 3 | L18: 2 | M18: =SUM(E18:L18)*D18 -> 66 | N18: 1.2 | O18: 0.75 | P18: 1.8 | Q18: =M18*N18*O18*P18 -> 106.92 | R18: =(Q18*25)/55 -> 48.6 | S18: =(Q18*20)/55 -> 38.88 | T18: =SUM(Q18:S18) -> 194.4
B19: 6 | C19: MFI-06: Copiloto Farmacoterapêutico Inteligente (RAG Clínico) | D19: 2 | E19: 2 | F19: 3 | G19: 1 | H19: 3 | I19: 2 | J19: 3 | K19: 3 | L19: 2 | M19: =SUM(E19:L19)*D19 -> 38 | N19: 1.2 | O19: 1 | P19: 2.4 | Q19: =M19*N19*O19*P19 -> 109.44 | R19: =(Q19*25)/55 -> 49.75 | S19: =(Q19*20)/55 -> 39.8 | T19: =SUM(Q19:S19) -> 198.98
B20: 7 | C20: MFI-07: Faturamento Hospitalar, Auditoria e Guias TISS/TUSS | D20: 2 | E20: 3 | F20: 3 | G20: 3 | H20: 2 | I20: 1 | J20: 3 | K20: 3 | L20: 2 | M20: =SUM(E20:L20)*D20 -> 40 | N20: 1.2 | O20: 0.75 | P20: 1.8 | Q20: =M20*N20*O20*P20 -> 64.8 | R20: =(Q20*25)/55 -> 29.45 | S20: =(Q20*20)/55 -> 23.56 | T20: =SUM(Q20:S20) -> 117.82
B21: 8 | C21: MFI-08: Gateway de Higienização de PII (LGPD) e Trilha WORM | D21: 2 | E21: 0 | F21: 3 | G21: 1 | H21: 1 | I21: 2 | J21: 3 | K21: 3 | L21: 1 | M21: =SUM(E21:L21)*D21 -> 28 | N21: 1.2 | O21: 0.75 | P21: 1.8 | Q21: =M21*N21*O21*P21 -> 45.36 | R21: =(Q21*25)/55 -> 20.62 | S21: =(Q21*20)/55 -> 16.49 | T21: =SUM(Q21:S21) -> 82.47
B22: Total | D22: =SUM(D14:D21) -> 17 | E22: =SUM(E14:E21) -> 6 | F22: =SUM(F14:F21) -> 4 | G22: =SUM(G14:G21) -> 1 | H22: =SUM(H14:H21) -> 3 | I22: =SUM(I14:I21) -> 3 | J22: =SUM(J14:J21) -> 5 | K22: =SUM(K14:K21) -> 2 | ... M22: =SUM(M14:M21) -> 41 | Q22: =SUM(Q14:Q21) -> 594.72 | R22: =SUM(R14:R21) -> 270.33 | S22: =SUM(S14:S21) -> 216.26 | T22: =SUM(T14:T21) -> 1081.31
B24: Resumo de Esforço Calculado
B25: Projeto | C25: =R22 -> 270.33
B26: Codificação | C26: =Q22 -> 594.72
B27: Testes | C27: =S22 -> 216.26
B28: Esforço Bruto | C28: =SUM(C25:C27) -> 1081.31
D30: Prg tela | E30: Prg sem tela / com Relat / Tabelas | F30: Plataforma / Linguagem / Tipo Serviço | G30: Interfaces | H30: Esforço Serviço | I30: Reutilização | J30: Manutenção | K30: Tipo Recurso
D31: 0 | E31: 0 | F31: 1 | G31: 0 | H31: 1 | I31: 1 | J31: 0.6 | K31: Junior
D32: 2 | E32: 1 | F32: 2 | G32: 2 | H32: 1.2 | I32: 0.75 | J32: 0.9 | K32: Pleno
D33: 3 | E33: 2 | F33: 3 | G33: 3 | I33: 0.5 | J33: 1.2 | K33: Senior
D34: 4 | E34: 3 | J34: 1.8
J35: 2.4
J36: 3.6
J37: 4.8
C46: =NA() -> #N/A

Sheet Recursos
C1: Métrica Função de Implementação - Estimativa
B6: Função de Implementação | D6: Total de Esforço Bruto (Horas) | E6: Recursos | G6: Total de Esforço (Horas)
B7: Identificação | C7: Descrição | E7: Nivel | F7: % Redução
B8: 1 | C8: MFI-01: Cadastro de Pacientes, Validação CNS/CPF e Recepção | D8: =Estimativa!T14 -> 70.69 | E8: Nível 2 | F8: 15 | G8: =ROUND(D8-(D8*(F8/100)),0) -> 60
B9: 2 | C9: MFI-02: Acolhimento e Triagem de Manchester com Voz | D9: =Estimativa!T15 -> 111.93 | E9: Nível 2 | F9: 15 | G9: =ROUND(D9-(D9*(F9/100)),0) -> 95
B10: 3 | C10: MFI-03: Motor Preditivo de Sepse e Deterioração (qSOFA/NEWS2) | D10: =Estimativa!T16 -> 198.98 | E10: Nível 3 | F10: 25 | G10: =ROUND(D10-(D10*(F10/100)),0) -> 149
B11: 4 | C11: MFI-04: Gestão Dinâmica e Alocação Preditiva de Leitos (LOS) | D11: =Estimativa!T17 -> 106.04 | E11: Nível 2 | F11: 15 | G11: =ROUND(D11-(D11*(F11/100)),0) -> 90
B12: 5 | C12: MFI-05: Prontuário Eletrônico (PEP) e Evolução Estruturada | D12: =Estimativa!T18 -> 194.4 | E12: Nível 3 | F12: 25 | G12: =ROUND(D12-(D12*(F12/100)),0) -> 146
B13: 6 | C13: MFI-06: Copiloto Farmacoterapêutico Inteligente (RAG Clínico) | D13: =Estimativa!T19 -> 198.98 | E13: Nível 3 | F13: 25 | G13: =ROUND(D13-(D13*(F13/100)),0) -> 149
B14: 7 | C14: MFI-07: Faturamento Hospitalar, Auditoria e Guias TISS/TUSS | D14: =Estimativa!T20 -> 117.82 | E14: Nível 2 | F14: 15 | G14: =ROUND(D14-(D14*(F14/100)),0) -> 100
B15: 8 | C15: MFI-08: Gateway de Higienização de PII (LGPD) e Trilha WORM | D15: =Estimativa!T21 -> 82.47 | E15: Nível 3 | F15: 25 | G15: =ROUND(D15-(D15*(F15/100)),0) -> 62
B16: Total | D16: =SUM(D8:D15) -> 1081.31 | G16: =SUM(G8:G15) -> 851
B18: Resumo de Esforço Calculado
B19: Projeto | C19: =Estimativa!R22 -> 270.33
B20: Codificação | C20: =Estimativa!Q22 -> 594.72
B21: Testes | C21: =Estimativa!S22 -> 216.26
B22: Esforço Bruto | C22: =D16 -> 1081.31
B23: Total Esforço | C23: =G16 -> 851
D27: Nivel Recurso
D28: Nível 1
D29: Nível 2
D30: Nível 3

Sheet Instruções
B2: Orientações para um bom preenchimento da planilha de Estimativa
B4: Existem colunas que possuem comentários sobre qual conteúdo pode ser aceito.
B5: Basta passar o mouse sobre o título da coluna para ver a explicação.
B6: Abaixo estão todos os comentários destas colunas, organizados por item
B8: Aba Estimativa
B10: Projeto: | C10: Nome do projeto envolvido na estimativa
B12: Estimado por: | C12: Nome do Analista responsável pela estimativa do projeto
B14: Data da Estimativa: | C14: Data efetiva em que a estimativa foi concluída
B16: Função de Implementação: | C16: Identificação = Pode ser um código para diferenciar cada implementação Ex.: N° do Caso de Unso, RN01.
C17: Descriçã = Breve descritivo da funcionalidade
B19: Qtde.de Programas: | C19: Informar a quantidade de Programas, da Função de Implementação, que serão criados ou mantidos.
C20: Os programas obrigatoriamente devem ter as mesmas características (similares) para que possam
C21: ser agrupados e quantificados para uma mesma "Função de Implementação".
C22: Caso contrário, informar a função em uma outra linha de "Função de Implementação"
B24: Características Internas: | C24: Programas COM Tela:
C25: Analisar quanto ao número de campos na tela. Os valores válidos são:
C26: Campos na Tela | F26: Dificuldade | H26: Pontos
C27: até 4 campos | F27: Simples | H27: 2
C28: de 5 a 10 campos | F28: Média | H28: 3
C29: acima de 10 campos | F29: Complexa | H29: 4
C31: Programas SEM Tela:
C32: Analisar quanto ao número de campos referenciados. Os valores válidos são:
C33: Campos Referenciados | F33: Dificuldade | H33: Pontos
C34: até 4 campos | F34: Simples | H34: 1
C35: de 5 a 10 campos | F35: Média | H35: 2
C36: acima de 10 campos | F36: Complexa | H36: 3
C38: Programas com Relatório:
C39: Considerar as regras e os detalhes de quebra de cada relatório. Os valores válidos são:
C40: Campos Envolvidos | F40: Dificuldade | H40: Pontos
C41: até 8 campos | F41: Simples | H41: 1
C42: de 9 a 16 campos | F42: Média | H42: 2
C43: acima de 16 campos | F43: Complexa | H43: 3
C45: Qtde de Tabelas:
C46: Analisar quanto à quantidade de tabelas físicas referenciadas. Os valores válidos são:
C47: Qtde | F47: Dificuldade | H47: Pontos
C48: até 6 tabelas | F48: Simples | H48: 1
C49: de 7 a 15 tabelas | F49: Média | H49: 2
C50: acima de 15 tabelas | F50: Complexa | H50: 3
B52: Tipo de Serviço | C52: Plataforma:
C53: Analisar quanto à Plataforma utilizada. Os valores válidos são:
...
